Workbook

Sheet BvA report
B3: GL Account | C3: Budget | D3: Actuals | E3: Variance ($) | F3: Variance (%) | G3: Commentory
B5: Revenue | C5: 250000 | D5: 210000 | E5: =D5-C5 -> -40000 | F5: =(D5-C5)/C5 -> -0.16 | G5: Missed target (-16%) driven by Enterprise contract slip to Jan-25 and unexpected spike in Pro churn.
B6: COGS | C6: 50000 | D6: 55000 | E6: =D6-C6 -> 5000 | F6: =(D6-C6)/C6 -> 0.1 | G6: Unfavorable variance due to 10% price increase from AWS server provider.
B7: Salaries | C7: 150000 | D7: 140000 | E7: =D7-C7 -> -10000 | F7: =(D7-C7)/C7 -> -0.066666667 | G7: Favorable variance due to 2-week delay in hiring Senior Developer
B8: Marketing | C8: 20000 | D8: 40000 | E8: =D8-C8 -> 20000 | F8: =(D8-C8)/C8 -> 1 | G8: Overspend driven by accidental doubling of LinkedIn Ad budget; corrective action taken
B9: Software/Rent | C9: 10000 | D9: 10000 | E9: =D9-C9 -> 0 | F9: =(D9-C9)/C9 -> 0 | G9: On plan
B10: Travel | C10: 5000 | D10: 12000 | E10: =D10-C10 -> 7000 | F10: =(D10-C10)/C10 -> 1.4 | G10: Unplanned expense due to emergency Sales team onsite visit to close Enterprise deal.
K22: Created By : Vishwaradhya Ms | FP&A Startup Finance Analyst
K23: Model created manually for demonstration purpose

Sheet Sales (ROI)
C2: Line Item | E2: Month 1 | F2: Month 2 | G2: Month 3 | H2: Month 4 | I2: Month 5 | J2: Month 6 | K2: Month 7 | L2: Month 8 | M2: Month 9 | N2: Month 10 | O2: Month 11 | P2: Month 12
B4: REVENUE
C5: Sales Revenue | E5: 0 | F5: 0 | G5: 0 | H5: 30000 | I5: 30000 | J5: 30000 | K5: 30000 | L5: 30000 | M5: 30000 | N5: 30000 | O5: 30000 | P5: 30000
B7: COSTS
C8: Base Salary | E8: 5000 | F8: =E8 -> 5000 | G8: =F8 -> 5000 | H8: =G8 -> 5000 | I8: =H8 -> 5000 | J8: =I8 -> 5000 | K8: =J8 -> 5000 | L8: =K8 -> 5000 | M8: =L8 -> 5000 | ... P8: =O8 -> 5000
C9: Commission | E9: =E5*0.1 -> 0 | F9: =F5*0.1 -> 0 | G9: =G5*0.1 -> 0 | H9: =H5*0.1 -> 3000 | I9: =I5*0.1 -> 3000 | J9: =J5*0.1 -> 3000 | K9: =K5*0.1 -> 3000 | L9: =L5*0.1 -> 3000 | ... P9: =P5*0.1 -> 3000
C10: One-Time Costs | E10: 12000 | F10: 0 | G10: 0 | H10: 0 | I10: 0 | J10: 0 | K10: 0 | L10: 0 | M10: 0 | N10: 0 | O10: 0 | P10: 0
C11: TOTAL COST | E11: =SUM(E8:E10) -> 17000 | F11: =SUM(F8:F10) -> 5000 | G11: =SUM(G8:G10) -> 5000 | H11: =SUM(H8:H10) -> 8000 | I11: =SUM(I8:I10) -> 8000 | J11: =SUM(J8:J10) -> 8000 | K11: =SUM(K8:K10) -> 8000 | L11: =SUM(L8:L10) -> 8000 | ... P11: =SUM(P8:P10) -> 8000
B13: RETURN
C14: Net Profit | E14: =E5-E11 -> -17000 | F14: =F5-F11 -> -5000 | G14: =G5-G11 -> -5000 | H14: =H5-H11 -> 22000 | I14: =I5-I11 -> 22000 | J14: =J5-J11 -> 22000 | K14: =K5-K11 -> 22000 | L14: =L5-L11 -> 22000 | ... P14: =P5-P11 -> 22000
C15: Cumulative | E15: =E14 -> -17000 | F15: =E15+F14 -> -22000 | G15: =F15+G14 -> -27000 | H15: =G15+H14 -> -5000 | I15: =H15+I14 -> 17000 | J15: =I15+J14 -> 39000 | K15: =J15+K14 -> 61000 | L15: =K15+L14 -> 83000 | M15: =L15+M14 -> 105000 | ... P15: =O15+P14 -> 171000
B20: The Inputs
B22: Base Salary | C22: $5000
B23: Commission | C23: 0.1
B24: Target Quota | C24: $30000
B25: Ramp time | C25: 3 Months
B26: One-Time Costs | C26: $12000
P30: Created By : Vishwaradhya Ms | FP&A Startup Finance Analyst
P31: Model created manually for demonstration purpose

Sheet Revenue Report
B3: PRO CUSTOMERS
B5: Line Item | D5: Jan | E5: Feb | F5: Mar | G5: Apr | H5: May | I5: Jun | J5: Jul | K5: Aug | L5: Sep | M5: Oct | N5: Nov | O5: Dec
B7: Beginning Pro Customers | D7: 500 | E7: =D12 -> 525 | F7: =E12 -> 606.25 | G7: =F12 -> 696.5625 | H7: =G12 -> 796.39062 | I7: =H12 -> 906.21016 | J7: =I12 -> 1026.5207 | K7: =J12 -> 1157.8467 | L7: =K12 -> 1300.739 | ... O7: =N12 -> 1804.743
B9: New Customers | D9: 50 | E9: 55 | F9: 60 | G9: 65 | H9: 70 | I9: 75 | J9: 80 | K9: 85 | L9: 90 | M9: 95 | N9: 100 | O9: 105
B10: Churn Count | D10: =D7*5% -> 25 | E10: =E7*5% -> 26.25 | F10: =F7*5% -> 30.3125 | G10: =G7*5% -> 34.828125 | H10: =H7*5% -> 39.819531 | I10: =I7*5% -> 45.310508 | J10: =J7*5% -> 51.326033 | K10: =K7*5% -> 57.892335 | ... O10: =O7*5% -> 90.237151
B12: Ending Pro Customers | D12: =D7+D9-D10 -> 525 | E12: =SUM(E7:E10) -> 606.25 | F12: =SUM(F7:F10) -> 696.5625 | G12: =SUM(G7:G10) -> 796.39062 | H12: =SUM(H7:H10) -> 906.21016 | I12: =SUM(I7:I10) -> 1026.5207 | J12: =SUM(J7:J10) -> 1157.8467 | K12: =SUM(K7:K10) -> 1300.739 | L12: =SUM(L7:L10) -> 1455.776 | ... O12: =SUM(O7:O10) -> 1999.9802
B14: Pro Revenue | D14: =D12*50 -> 26250 | E14: =E12*50 -> 30312.5 | F14: =F12*50 -> 34828.125 | G14: =G12*50 -> 39819.531 | H14: =H12*50 -> 45310.508 | I14: =I12*50 -> 51326.033 | J14: =J12*50 -> 57892.335 | K14: =K12*50 -> 65036.952 | ... O14: =O12*50 -> 99999.009
B17: ENTERPRISE CUSTOMERS
B19: Line Item | D19: Jan | E19: Feb | F19: Mar | G19: Apr | H19: May | I19: Jun | J19: Jul | K19: Aug | L19: Sep | M19: Oct | N19: Nov | O19: Dec
B21: Beginning Ent Customers | D21: 20 | E21: =D26 -> 21.8 | F21: =E26 -> 24.018 | G21: =F26 -> 26.25818 | H21: =G26 -> 29.520762 | I21: =H26 -> 32.815969 | J21: =I26 -> 36.144129 | K21: =J26 -> 40.50557 | L21: =K26 -> 44.910626 | ... O21: =N26 -> 60.401863
B23: New Customers | D23: 2 | E23: 2 | F23: 2 | G23: 3 | H23: 3 | I23: 3 | J23: 4 | K23: 4 | L23: 4 | M23: 5 | N23: 5 | O23: 5
B24: Churn Count | D24: =D21*1% -> 0.2 | E24: =E21*1% -> 0.218 | F24: =F21*1% -> 0.24018 | G24: =G21*1% -> 0.2625818 | H24: =H21*1% -> 0.29520762 | I24: =I21*1% -> 0.32815969 | J24: =J21*1% -> 0.36144129 | K24: =K21*1% -> 0.4050557 | ... O24: =O21*1% -> 0.60401863
B26: Ending Ent Customers | D26: =D21+D23-D24 -> 21.8 | E26: =SUM(E21:E25) -> 24.018 | F26: =SUM(F21:F24) -> 26.25818 | G26: =SUM(G21:G24) -> 29.520762 | H26: =SUM(H21:H24) -> 32.815969 | I26: =SUM(I21:I24) -> 36.144129 | J26: =SUM(J21:J24) -> 40.50557 | K26: =SUM(K21:K24) -> 44.910626 | L26: =SUM(L21:L24) -> 49.359732 | M26: =SUM(M21:M24) -> 54.85333 | ... O26: =SUM(O21:O24) -> 66.005882
B28: ENT Revenue | D28: =D26*1000 -> 21800 | E28: =E26*1000 -> 24018 | F28: =F26*1000 -> 26258.18 | G28: =G26*1000 -> 29520.762 | H28: =H26*1000 -> 32815.969 | I28: =I26*1000 -> 36144.129 | J28: =J26*1000 -> 40505.57 | K28: =K26*1000 -> 44910.626 | ... O28: =O26*1000 -> 66005.882
B32: The Inputs
B34: Pro price | C34: $50
B35: Entprise Price | C35: $1000
B36: Pro Churn | C36: 0.05
B37: Enterprise Churn | C37: 0.01
B41: HEADCOUNT & OPEX
B43: Role | D43: Jan | E43: Feb | F43: Mar | G43: Apr | H43: May | I43: Jun | J43: Jul | K43: Aug | L43: Sep | M43: Oct | N43: Nov | O43: Dec
B45: R&D Headcount | D45: 5 | E45: 5 | F45: 6 | G45: 6 | H45: 7 | I45: 7 | J45: 8 | K45: 8 | L45: 9 | M45: 9 | N45: 10 | O45: 10
B46: Salaries (R&D) | D46: =D45*10000 -> 50000 | E46: =E45*10000 -> 50000 | F46: =F45*10000 -> 60000 | G46: =G45*10000 -> 60000 | H46: =H45*10000 -> 70000 | I46: =I45*10000 -> 70000 | J46: =J45*10000 -> 80000 | K46: =K45*10000 -> 80000 | ... O46: =O45*10000 -> 100000
B48: Sales Headcount | D48: 2 | E48: 2 | F48: 2 | G48: 3 | H48: 3 | I48: 3 | J48: 4 | K48: 4 | L48: 4 | M48: 5 | N48: 5 | O48: 5
B49: Salaries (Sales) | D49: =D48*6000 -> 12000 | E49: =E48*6000 -> 12000 | F49: =F48*6000 -> 12000 | G49: =G48*6000 -> 18000 | H49: =H48*6000 -> 18000 | I49: =I48*6000 -> 18000 | J49: =J48*6000 -> 24000 | K49: =K48*6000 -> 24000 | ... O49: =O48*6000 -> 30000
B51: G&A Headcount | D51: 2 | E51: 2 | F51: 2 | G51: 2 | H51: 2 | I51: 2 | J51: 2 | K51: 2 | L51: 2 | M51: 2 | N51: 2 | O51: 2
B52: Salaries (G&A) | D52: =D51*8000 -> 16000 | E52: =E51*8000 -> 16000 | F52: =F51*8000 -> 16000 | G52: =G51*8000 -> 16000 | H52: =H51*8000 -> 16000 | I52: =I51*8000 -> 16000 | J52: =J51*8000 -> 16000 | K52: =K51*8000 -> 16000 | ... O52: =O51*8000 -> 16000
B54: Hosting Costs | D54: {=(D12:O12+D26:O26)*5} -> 2734 | E54: 3151.34 | F54: 3614.1034 | G54: 4129.5569 | H54: 4695.1306 | I54: 5313.324 | J54: 5991.7613 | K54: 6728.2483 | L54: 7525.6786 | M54: 8392.0906 | N54: 9325.7244 | O54: 10329.93
B57: The Inputs
B59: Salary (R&D) | D59: $10,000 / mo
B60: Salary (Sales) | D60: $6,000 / mo
B61: Hosting Cost | D61: $5.00 per Customer
B62: Salaries (G&A) | D62: $8000 for admin
A65: 1 | B65: Payment Processing Fees (COGS)
B66: Assumption: 3% of Total Revenue
B67: Why: Stripe/PayPal takes a cut of every sale.
B68: Values | D68: {=(D14:O14+D28:O28)*3%} -> 1441.5 | E68: 1629.915 | F68: 1832.5892 | G68: 2080.2088 | H68: 2343.7943 | I68: 2624.1049 | J68: 2951.9372 | K68: 3298.4273 | L68: 3664.4559 | M68: 4080.9471 | N68: 4519.1704 | O68: 4980.1467
A70: 2 | B70: Premium Support Costs (COGS)
B71: Assumption: $10.00 per Enterprise Customer.
B72: Why: Enterprise clients need human support, which costs money.
...

Sheet Financial Statements
A2: x
B4: Income Statement | D4: Jan | E4: Feb | F4: Mar | G4: Apr | H4: May | I4: Jun | J4: Jul | K4: Aug | L4: Sep | M4: Oct | N4: Nov | O4: Dec
B5: REVENUE
B7: Pro Revenue | D7: {='Revenue Report'!D14:O14} -> 26250 | E7: 30312.5 | F7: 34828.125 | G7: 39819.531 | H7: 45310.508 | I7: 51326.033 | J7: 57892.335 | K7: 65036.952 | L7: 72788.799 | M7: 81178.239 | N7: 90237.151 | O7: 99999.009
B8: Enterprise Revenue | D8: {='Revenue Report'!D28:O28} -> 21800 | E8: 24018 | F8: 26258.18 | G8: 29520.762 | H8: 32815.969 | I8: 36144.129 | J8: 40505.57 | K8: 44910.626 | L8: 49359.732 | M8: 54853.33 | N8: 60401.863 | O8: 66005.882
B9: Total Revenue | D9: =SUM(D7:D8) -> 48050 | E9: =SUM(E7:E8) -> 54330.5 | F9: =SUM(F7:F8) -> 61086.305 | G9: =SUM(G7:G8) -> 69340.293 | H9: =SUM(H7:H8) -> 78126.477 | I9: =SUM(I7:I8) -> 87470.162 | J9: =SUM(J7:J8) -> 98397.905 | K9: =SUM(K7:K8) -> 109947.58 | ... O9: =SUM(O7:O8) -> 166004.89
B11: COST OF SALES (COGS)
B13: Hosting Costs | D13: {=_xlfn.ANCHORARRAY('Revenue Report'!D54)} -> 2734 | E13: 3151.34 | F13: 3614.1034 | G13: 4129.5569 | H13: 4695.1306 | I13: 5313.324 | J13: 5991.7613 | K13: 6728.2483 | L13: 7525.6786 | M13: 8392.0906 | N13: 9325.7244 | O13: 10329.93
B14: Payment Fees | D14: {=_xlfn.ANCHORARRAY('Revenue Report'!D68)} -> 1441.5 | E14: 1629.915 | F14: 1832.5892 | G14: 2080.2088 | H14: 2343.7943 | I14: 2624.1049 | J14: 2951.9372 | K14: 3298.4273 | L14: 3664.4559 | M14: 4080.9471 | N14: 4519.1704 | O14: 4980.1467
B15: Support Costs | D15: {=_xlfn.ANCHORARRAY('Revenue Report'!D73)} -> 218 | E15: 240.18 | F15: 262.5818 | G15: 295.20762 | H15: 328.15969 | I15: 361.44129 | J15: 405.0557 | K15: 449.10626 | L15: 493.59732 | M15: 548.5333 | N15: 604.01863 | O15: 660.05882
B16: Total COGS | D16: =SUM(D13:D15) -> 4393.5 | E16: =SUM(E13:E15) -> 5021.435 | F16: =SUM(F13:F15) -> 5709.2743 | G16: =SUM(G13:G15) -> 6504.9733 | H16: =SUM(H13:H15) -> 7367.0846 | I16: =SUM(I13:I15) -> 8298.8701 | J16: =SUM(J13:J15) -> 9348.7542 | K16: =SUM(K13:K15) -> 10475.782 | ... O16: =SUM(O13:O15) -> 15970.136
B18: GROSS PROFIT | D18: =D9-D16 -> 43656.5 | E18: =E9-E16 -> 49309.065 | F18: =F9-F16 -> 55377.031 | G18: =G9-G16 -> 62835.32 | H18: =H9-H16 -> 70759.393 | I18: =I9-I16 -> 79171.292 | J18: =J9-J16 -> 89049.151 | K18: =K9-K16 -> 99471.796 | ... O18: =O9-O16 -> 150034.75
B19: Gross Margin % | D19: =D18/D9 -> 0.908564 | E19: =E18/E9 -> 0.90757613 | F19: =F18/F9 -> 0.90653757 | G19: =G18/G9 -> 0.90618769 | H19: =H18/H9 -> 0.9057031 | I19: =I18/I9 -> 0.90512342 | J19: =J18/J9 -> 0.90499031 | K19: =K18/K9 -> 0.90472021 | ... O19: =O18/O9 -> 0.9037972
B21: OPERATING EXPENSES
B22: R&D Salaries | D22: {='Revenue Report'!D46:O46} -> 50000 | E22: 50000 | F22: 60000 | G22: 60000 | H22: 70000 | I22: 70000 | J22: 80000 | K22: 80000 | L22: 90000 | M22: 90000 | N22: 100000 | O22: 100000
B23: Sales Salaries | D23: {='Revenue Report'!D49:O49} -> 12000 | E23: 12000 | F23: 12000 | G23: 18000 | H23: 18000 | I23: 18000 | J23: 24000 | K23: 24000 | L23: 24000 | M23: 30000 | N23: 30000 | O23: 30000
B24: G&A Salaries | D24: {='Revenue Report'!D52:O52} -> 16000 | E24: 16000 | F24: 16000 | G24: 16000 | H24: 16000 | I24: 16000 | J24: 16000 | K24: 16000 | L24: 16000 | M24: 16000 | N24: 16000 | O24: 16000
B25: Office & Overhead | D25: {=_xlfn.ANCHORARRAY('Revenue Report'!D78)} -> 18000 | E25: 18000 | F25: 20000 | G25: 22000 | H25: 24000 | I25: 24000 | J25: 28000 | K25: 28000 | L25: 30000 | M25: 32000 | N25: 34000 | O25: 34000
B26: Marketing | D26: {='Revenue Report'!D82:O82} -> 15000 | E26: 15000 | F26: 20000 | G26: 20000 | H26: 25000 | I26: 25000 | J26: 30000 | K26: 30000 | L26: 35000 | M26: 35000 | N26: 40000 | O26: 50000
B27: Total OpEx | D27: =SUM(D22:D26) -> 111000 | E27: =SUM(E22:E26) -> 111000 | F27: =SUM(F22:F26) -> 128000 | G27: =SUM(G22:G26) -> 136000 | H27: =SUM(H22:H26) -> 153000 | I27: =SUM(I22:I26) -> 153000 | J27: =SUM(J22:J26) -> 178000 | K27: =SUM(K22:K26) -> 178000 | ... O27: =SUM(O22:O26) -> 230000
B29: NET INCOME | D29: =D18-D27 -> -67343.5 | E29: =E18-E27 -> -61690.935 | F29: =F18-F27 -> -72622.969 | G29: =G18-G27 -> -73164.68 | H29: =H18-H27 -> -82240.607 | I29: =I18-I27 -> -73828.708 | J29: =J18-J27 -> -88950.849 | K29: =K18-K27 -> -78528.204 | ... O29: =O18-O27 -> -79965.246
M43: Created By : Vishwaradhya Ms | FP&A Startup Finance Analyst
M44: Model created manually for demonstration purpose
